// Decompiled by Jad v1.5.8g. Copyright 2001 Pavel Kouznetsov.
// Jad home page: http://www.kpdus.com/jad.html
// Decompiler options: packimports(3) braces deadcode fieldsfirst 

package net.minecraft.src;

import java.util.List;
import java.util.Random;

// Referenced classes of package net.minecraft.src:
//            ComponentVillage, StructureBoundingBox, StructureComponent, Block, 
//            World

public class ComponentVillageHouse3 extends ComponentVillage
{

    private int field_35373_a;

    public ComponentVillageHouse3(int i, Random random, StructureBoundingBox structureboundingbox, int j)
    {
        super(i);
        field_35373_a = -1;
        coordBaseMode = j;
        boundingBox = structureboundingbox;
    }

    public void buildComponent(StructureComponent structurecomponent, List list, Random random)
    {
    }

    public static ComponentVillageHouse3 func_35372_a(List list, Random random, int i, int j, int k, int l, int i1)
    {
        StructureBoundingBox structureboundingbox = StructureBoundingBox.getComponentToAddBoundingBox(i, j, k, 0, 0, 0, 9, 7, 12, l);
        if(!canVillageGoDeeper(structureboundingbox) || StructureComponent.canFitInside(list, structureboundingbox) != null)
        {
            return null;
        } else
        {
            return new ComponentVillageHouse3(i1, random, structureboundingbox, l);
        }
    }

    public boolean addComponentParts(World world, Random random, StructureBoundingBox structureboundingbox)
    {
        if(field_35373_a < 0)
        {
            field_35373_a = getFoundationLevel(world, structureboundingbox);
            if(field_35373_a < 0)
            {
                return true;
            }
            boundingBox.offset(0, ((field_35373_a - boundingBox.y2) + 7) - 1, 0);
        }
        fillWithBlocks(world, structureboundingbox, 1, 1, 1, 7, 4, 4, 0, 0, false);
        fillWithBlocks(world, structureboundingbox, 2, 1, 6, 8, 4, 10, 0, 0, false);
        fillWithBlocks(world, structureboundingbox, 2, 0, 5, 8, 0, 10, Block.planks.blockID, Block.planks.blockID, false);
        fillWithBlocks(world, structureboundingbox, 1, 0, 1, 7, 0, 4, Block.planks.blockID, Block.planks.blockID, false);
        fillWithBlocks(world, structureboundingbox, 0, 0, 0, 0, 3, 5, Block.cobblestone.blockID, Block.cobblestone.blockID, false);
        fillWithBlocks(world, structureboundingbox, 8, 0, 0, 8, 3, 10, Block.cobblestone.blockID, Block.cobblestone.blockID, false);
        fillWithBlocks(world, structureboundingbox, 1, 0, 0, 7, 2, 0, Block.cobblestone.blockID, Block.cobblestone.blockID, false);
        fillWithBlocks(world, structureboundingbox, 1, 0, 5, 2, 1, 5, Block.cobblestone.blockID, Block.cobblestone.blockID, false);
        fillWithBlocks(world, structureboundingbox, 2, 0, 6, 2, 3, 10, Block.cobblestone.blockID, Block.cobblestone.blockID, false);
        fillWithBlocks(world, structureboundingbox, 3, 0, 10, 7, 3, 10, Block.cobblestone.blockID, Block.cobblestone.blockID, false);
        fillWithBlocks(world, structureboundingbox, 1, 2, 0, 7, 3, 0, Block.planks.blockID, Block.planks.blockID, false);
        fillWithBlocks(world, structureboundingbox, 1, 2, 5, 2, 3, 5, Block.planks.blockID, Block.planks.blockID, false);
        fillWithBlocks(world, structureboundingbox, 0, 4, 1, 8, 4, 1, Block.planks.blockID, Block.planks.blockID, false);
        fillWithBlocks(world, structureboundingbox, 0, 4, 4, 3, 4, 4, Block.planks.blockID, Block.planks.blockID, false);
        fillWithBlocks(world, structureboundingbox, 0, 5, 2, 8, 5, 3, Block.planks.blockID, Block.planks.blockID, false);
        placeBlockAtCurrentPosition(world, Block.planks.blockID, 0, 0, 4, 2, structureboundingbox);
        placeBlockAtCurrentPosition(world, Block.planks.blockID, 0, 0, 4, 3, structureboundingbox);
        placeBlockAtCurrentPosition(world, Block.planks.blockID, 0, 8, 4, 2, structureboundingbox);
        placeBlockAtCurrentPosition(world, Block.planks.blockID, 0, 8, 4, 3, structureboundingbox);
        placeBlockAtCurrentPosition(world, Block.planks.blockID, 0, 8, 4, 4, structureboundingbox);
        int i = func_35301_c(Block.stairCompactPlanks.blockID, 3);
        int j = func_35301_c(Block.stairCompactPlanks.blockID, 2);
        for(int k = -1; k <= 2; k++)
        {
            for(int i1 = 0; i1 <= 8; i1++)
            {
                placeBlockAtCurrentPosition(world, Block.stairCompactPlanks.blockID, i, i1, 4 + k, k, structureboundingbox);
                if((k > -1 || i1 <= 1) && (k > 0 || i1 <= 3) && (k > 1 || i1 <= 4 || i1 >= 6))
                {
                    placeBlockAtCurrentPosition(world, Block.stairCompactPlanks.blockID, j, i1, 4 + k, 5 - k, structureboundingbox);
                }
            }

        }

        fillWithBlocks(world, structureboundingbox, 3, 4, 5, 3, 4, 10, Block.planks.blockID, Block.planks.blockID, false);
        fillWithBlocks(world, structureboundingbox, 7, 4, 2, 7, 4, 10, Block.planks.blockID, Block.planks.blockID, false);
        fillWithBlocks(world, structureboundingbox, 4, 5, 4, 4, 5, 10, Block.planks.blockID, Block.planks.blockID, false);
        fillWithBlocks(world, structureboundingbox, 6, 5, 4, 6, 5, 10, Block.planks.blockID, Block.planks.blockID, false);
        fillWithBlocks(world, structureboundingbox, 5, 6, 3, 5, 6, 10, Block.planks.blockID, Block.planks.blockID, false);
        int l = func_35301_c(Block.stairCompactPlanks.blockID, 0);
        for(int j1 = 4; j1 >= 1; j1--)
        {
            placeBlockAtCurrentPosition(world, Block.planks.blockID, 0, j1, 2 + j1, 7 - j1, structureboundingbox);
            for(int l1 = 8 - j1; l1 <= 10; l1++)
            {
                placeBlockAtCurrentPosition(world, Block.stairCompactPlanks.blockID, l, j1, 2 + j1, l1, structureboundingbox);
            }

        }

        int k1 = func_35301_c(Block.stairCompactPlanks.blockID, 1);
        placeBlockAtCurrentPosition(world, Block.planks.blockID, 0, 6, 6, 3, structureboundingbox);
        placeBlockAtCurrentPosition(world, Block.planks.blockID, 0, 7, 5, 4, structureboundingbox);
        placeBlockAtCurrentPosition(world, Block.stairCompactPlanks.blockID, k1, 6, 6, 4, structureboundingbox);
        for(int i2 = 6; i2 <= 8; i2++)
        {
            for(int l2 = 5; l2 <= 10; l2++)
            {
                placeBlockAtCurrentPosition(world, Block.stairCompactPlanks.blockID, k1, i2, 12 - i2, l2, structureboundingbox);
            }

        }

        placeBlockAtCurrentPosition(world, Block.wood.blockID, 0, 0, 2, 1, structureboundingbox);
        placeBlockAtCurrentPosition(world, Block.wood.blockID, 0, 0, 2, 4, structureboundingbox);
        placeBlockAtCurrentPosition(world, Block.thinGlass.blockID, 0, 0, 2, 2, structureboundingbox);
        placeBlockAtCurrentPosition(world, Block.thinGlass.blockID, 0, 0, 2, 3, structureboundingbox);
        placeBlockAtCurrentPosition(world, Block.wood.blockID, 0, 4, 2, 0, structureboundingbox);
        placeBlockAtCurrentPosition(world, Block.thinGlass.blockID, 0, 5, 2, 0, structureboundingbox);
        placeBlockAtCurrentPosition(world, Block.wood.blockID, 0, 6, 2, 0, structureboundingbox);
        placeBlockAtCurrentPosition(world, Block.wood.blockID, 0, 8, 2, 1, structureboundingbox);
        placeBlockAtCurrentPosition(world, Block.thinGlass.blockID, 0, 8, 2, 2, structureboundingbox);
        placeBlockAtCurrentPosition(world, Block.thinGlass.blockID, 0, 8, 2, 3, structureboundingbox);
        placeBlockAtCurrentPosition(world, Block.wood.blockID, 0, 8, 2, 4, structureboundingbox);
        placeBlockAtCurrentPosition(world, Block.planks.blockID, 0, 8, 2, 5, structureboundingbox);
        placeBlockAtCurrentPosition(world, Block.wood.blockID, 0, 8, 2, 6, structureboundingbox);
        placeBlockAtCurrentPosition(world, Block.thinGlass.blockID, 0, 8, 2, 7, structureboundingbox);
        placeBlockAtCurrentPosition(world, Block.thinGlass.blockID, 0, 8, 2, 8, structureboundingbox);
        placeBlockAtCurrentPosition(world, Block.wood.blockID, 0, 8, 2, 9, structureboundingbox);
        placeBlockAtCurrentPosition(world, Block.wood.blockID, 0, 2, 2, 6, structureboundingbox);
        placeBlockAtCurrentPosition(world, Block.thinGlass.blockID, 0, 2, 2, 7, structureboundingbox);
        placeBlockAtCurrentPosition(world, Block.thinGlass.blockID, 0, 2, 2, 8, structureboundingbox);
        placeBlockAtCurrentPosition(world, Block.wood.blockID, 0, 2, 2, 9, structureboundingbox);
        placeBlockAtCurrentPosition(world, Block.wood.blockID, 0, 4, 4, 10, structureboundingbox);
        placeBlockAtCurrentPosition(world, Block.thinGlass.blockID, 0, 5, 4, 10, structureboundingbox);
        placeBlockAtCurrentPosition(world, Block.wood.blockID, 0, 6, 4, 10, structureboundingbox);
        placeBlockAtCurrentPosition(world, Block.planks.blockID, 0, 5, 5, 10, structureboundingbox);
        placeBlockAtCurrentPosition(world, 0, 0, 2, 1, 0, structureboundingbox);
        placeBlockAtCurrentPosition(world, 0, 0, 2, 2, 0, structureboundingbox);
        placeBlockAtCurrentPosition(world, Block.torchWood.blockID, 0, 2, 3, 1, structureboundingbox);
        placeDoorAtCurrentPosition(world, structureboundingbox, random, 2, 1, 0, func_35301_c(Block.doorWood.blockID, 1));
        fillWithBlocks(world, structureboundingbox, 1, 0, -1, 3, 2, -1, 0, 0, false);
        if(func_35297_a(world, 2, 0, -1, structureboundingbox) == 0 && func_35297_a(world, 2, -1, -1, structureboundingbox) != 0)
        {
            placeBlockAtCurrentPosition(world, Block.stairCompactCobblestone.blockID, func_35301_c(Block.stairCompactCobblestone.blockID, 3), 2, 0, -1, structureboundingbox);
        }
        for(int j2 = 0; j2 < 5; j2++)
        {
            for(int i3 = 0; i3 < 9; i3++)
            {
                clearCurrentPositionBlocksUpwards(world, i3, 7, j2, structureboundingbox);
                fillCurrentPositionBlocksDownwards(world, Block.cobblestone.blockID, 0, i3, -1, j2, structureboundingbox);
            }

        }

        for(int k2 = 5; k2 < 11; k2++)
        {
            for(int j3 = 2; j3 < 9; j3++)
            {
                clearCurrentPositionBlocksUpwards(world, j3, 7, k2, structureboundingbox);
                fillCurrentPositionBlocksDownwards(world, Block.cobblestone.blockID, 0, j3, -1, k2, structureboundingbox);
            }

        }

        func_40309_a(world, structureboundingbox, 4, 1, 2, 2);
        return true;
    }
}
